2021-06-23 16:10:37,051 ERROR: Exception on /reset_password_request [POST] [in /Users/vincentiuscalvin/anaconda3/envs/personal/lib/python3.8/site-packages/flask/app.py:1891
Traceback (most recent call last):
  File "/Users/vincentiuscalvin/anaconda3/envs/personal/lib/python3.8/site-packages/flask_mail.py", line 492, in send
    message.send(connection)
  File "/Users/vincentiuscalvin/anaconda3/envs/personal/lib/python3.8/site-packages/flask_mail.py", line 427, in send
    connection.send(self)
  File "/Users/vincentiuscalvin/anaconda3/envs/personal/lib/python3.8/site-packages/flask_mail.py", line 188, in send
    self.host.sendmail(sanitize_address(envelope_from or message.sender),
  File "/Users/vincentiuscalvin/anaconda3/envs/personal/lib/python3.8/smtplib.py", line 856, in sendmail
    self.ehlo_or_helo_if_needed()
  File "/Users/vincentiuscalvin/anaconda3/envs/personal/lib/python3.8/smtplib.py", line 604, in ehlo_or_helo_if_needed
    if not (200 <= self.ehlo()[0] <= 299):
  File "/Users/vincentiuscalvin/anaconda3/envs/personal/lib/python3.8/smtplib.py", line 444, in ehlo
    self.putcmd(self.ehlo_msg, name or self.local_hostname)
  File "/Users/vincentiuscalvin/anaconda3/envs/personal/lib/python3.8/smtplib.py", line 371, in putcmd
    self.send(str)
  File "/Users/vincentiuscalvin/anaconda3/envs/personal/lib/python3.8/smtplib.py", line 363, in send
    raise SMTPServerDisconnected('please run connect() first')
smtplib.SMTPServerDisconnected: please run connect() first

During handling of the above exception, another exception occurred:

Traceback (most recent call last):
  File "/Users/vincentiuscalvin/anaconda3/envs/personal/lib/python3.8/site-packages/flask/app.py", line 2447, in wsgi_app
    response = self.full_dispatch_request()
  File "/Users/vincentiuscalvin/anaconda3/envs/personal/lib/python3.8/site-packages/flask/app.py", line 1952, in full_dispatch_request
    rv = self.handle_user_exception(e)
  File "/Users/vincentiuscalvin/anaconda3/envs/personal/lib/python3.8/site-packages/flask/app.py", line 1821, in handle_user_exception
    reraise(exc_type, exc_value, tb)
  File "/Users/vincentiuscalvin/anaconda3/envs/personal/lib/python3.8/site-packages/flask/_compat.py", line 39, in reraise
    raise value
  File "/Users/vincentiuscalvin/anaconda3/envs/personal/lib/python3.8/site-packages/flask/app.py", line 1950, in full_dispatch_request
    rv = self.dispatch_request()
  File "/Users/vincentiuscalvin/anaconda3/envs/personal/lib/python3.8/site-packages/flask/app.py", line 1936, in dispatch_request
    return self.view_functions[rule.endpoint](**req.view_args)
  File "/Users/vincentiuscalvin/Documents/Supertype/Learning Flask/app/routes.py", line 154, in reset_password_request
    send_password_reset_email(user)
  File "/Users/vincentiuscalvin/Documents/Supertype/Learning Flask/app/email.py", line 13, in send_password_reset_email
    send_email('[CALVIN] Reset Your Password',
  File "/Users/vincentiuscalvin/Documents/Supertype/Learning Flask/app/email.py", line 9, in send_email
    mail.send(msg)
  File "/Users/vincentiuscalvin/anaconda3/envs/personal/lib/python3.8/site-packages/flask_mail.py", line 492, in send
    message.send(connection)
  File "/Users/vincentiuscalvin/anaconda3/envs/personal/lib/python3.8/site-packages/flask_mail.py", line 152, in __exit__
    self.host.quit()
  File "/Users/vincentiuscalvin/anaconda3/envs/personal/lib/python3.8/smtplib.py", line 988, in quit
    res = self.docmd("quit")
  File "/Users/vincentiuscalvin/anaconda3/envs/personal/lib/python3.8/smtplib.py", line 424, in docmd
    self.putcmd(cmd, args)
  File "/Users/vincentiuscalvin/anaconda3/envs/personal/lib/python3.8/smtplib.py", line 371, in putcmd
    self.send(str)
  File "/Users/vincentiuscalvin/anaconda3/envs/personal/lib/python3.8/smtplib.py", line 363, in send
    raise SMTPServerDisconnected('please run connect() first')
smtplib.SMTPServerDisconnected: please run connect() first
2021-06-23 16:13:00,001 INFO: My App Startup [in /Users/vincentiuscalvin/Documents/Supertype/Learning Flask/app/__init__.py:50
2021-06-23 16:13:19,860 ERROR: Exception on /reset_password_request [POST] [in /Users/vincentiuscalvin/anaconda3/envs/personal/lib/python3.8/site-packages/flask/app.py:1891
Traceback (most recent call last):
  File "/Users/vincentiuscalvin/anaconda3/envs/personal/lib/python3.8/site-packages/flask/app.py", line 2447, in wsgi_app
    response = self.full_dispatch_request()
  File "/Users/vincentiuscalvin/anaconda3/envs/personal/lib/python3.8/site-packages/flask/app.py", line 1952, in full_dispatch_request
    rv = self.handle_user_exception(e)
  File "/Users/vincentiuscalvin/anaconda3/envs/personal/lib/python3.8/site-packages/flask/app.py", line 1821, in handle_user_exception
    reraise(exc_type, exc_value, tb)
  File "/Users/vincentiuscalvin/anaconda3/envs/personal/lib/python3.8/site-packages/flask/_compat.py", line 39, in reraise
    raise value
  File "/Users/vincentiuscalvin/anaconda3/envs/personal/lib/python3.8/site-packages/flask/app.py", line 1950, in full_dispatch_request
    rv = self.dispatch_request()
  File "/Users/vincentiuscalvin/anaconda3/envs/personal/lib/python3.8/site-packages/flask/app.py", line 1936, in dispatch_request
    return self.view_functions[rule.endpoint](**req.view_args)
  File "/Users/vincentiuscalvin/Documents/Supertype/Learning Flask/app/routes.py", line 154, in reset_password_request
    send_password_reset_email(user)
  File "/Users/vincentiuscalvin/Documents/Supertype/Learning Flask/app/email.py", line 13, in send_password_reset_email
    send_email('[CALVIN] Reset Your Password',
  File "/Users/vincentiuscalvin/Documents/Supertype/Learning Flask/app/email.py", line 9, in send_email
    mail.send(msg)
  File "/Users/vincentiuscalvin/anaconda3/envs/personal/lib/python3.8/site-packages/flask_mail.py", line 491, in send
    with self.connect() as connection:
  File "/Users/vincentiuscalvin/anaconda3/envs/personal/lib/python3.8/site-packages/flask_mail.py", line 144, in __enter__
    self.host = self.configure_host()
  File "/Users/vincentiuscalvin/anaconda3/envs/personal/lib/python3.8/site-packages/flask_mail.py", line 165, in configure_host
    host.login(self.mail.username, self.mail.password)
  File "/Users/vincentiuscalvin/anaconda3/envs/personal/lib/python3.8/smtplib.py", line 734, in login
    raise last_exception
  File "/Users/vincentiuscalvin/anaconda3/envs/personal/lib/python3.8/smtplib.py", line 723, in login
    (code, resp) = self.auth(
  File "/Users/vincentiuscalvin/anaconda3/envs/personal/lib/python3.8/smtplib.py", line 646, in auth
    raise SMTPAuthenticationError(code, resp)
smtplib.SMTPAuthenticationError: (535, b'5.7.8 Username and Password not accepted. Learn more at\n5.7.8  https://support.google.com/mail/?p=BadCredentials g18sm1719652pfi.199 - gsmtp')
2021-06-23 16:14:26,421 ERROR: Exception on /reset_password_request [POST] [in /Users/vincentiuscalvin/anaconda3/envs/personal/lib/python3.8/site-packages/flask/app.py:1891
Traceback (most recent call last):
  File "/Users/vincentiuscalvin/anaconda3/envs/personal/lib/python3.8/site-packages/flask/app.py", line 2447, in wsgi_app
    response = self.full_dispatch_request()
  File "/Users/vincentiuscalvin/anaconda3/envs/personal/lib/python3.8/site-packages/flask/app.py", line 1952, in full_dispatch_request
    rv = self.handle_user_exception(e)
  File "/Users/vincentiuscalvin/anaconda3/envs/personal/lib/python3.8/site-packages/flask/app.py", line 1821, in handle_user_exception
    reraise(exc_type, exc_value, tb)
  File "/Users/vincentiuscalvin/anaconda3/envs/personal/lib/python3.8/site-packages/flask/_compat.py", line 39, in reraise
    raise value
  File "/Users/vincentiuscalvin/anaconda3/envs/personal/lib/python3.8/site-packages/flask/app.py", line 1950, in full_dispatch_request
    rv = self.dispatch_request()
  File "/Users/vincentiuscalvin/anaconda3/envs/personal/lib/python3.8/site-packages/flask/app.py", line 1936, in dispatch_request
    return self.view_functions[rule.endpoint](**req.view_args)
  File "/Users/vincentiuscalvin/Documents/Supertype/Learning Flask/app/routes.py", line 154, in reset_password_request
    send_password_reset_email(user)
  File "/Users/vincentiuscalvin/Documents/Supertype/Learning Flask/app/email.py", line 13, in send_password_reset_email
    send_email('[CALVIN] Reset Your Password',
  File "/Users/vincentiuscalvin/Documents/Supertype/Learning Flask/app/email.py", line 9, in send_email
    mail.send(msg)
  File "/Users/vincentiuscalvin/anaconda3/envs/personal/lib/python3.8/site-packages/flask_mail.py", line 491, in send
    with self.connect() as connection:
  File "/Users/vincentiuscalvin/anaconda3/envs/personal/lib/python3.8/site-packages/flask_mail.py", line 144, in __enter__
    self.host = self.configure_host()
  File "/Users/vincentiuscalvin/anaconda3/envs/personal/lib/python3.8/site-packages/flask_mail.py", line 165, in configure_host
    host.login(self.mail.username, self.mail.password)
  File "/Users/vincentiuscalvin/anaconda3/envs/personal/lib/python3.8/smtplib.py", line 734, in login
    raise last_exception
  File "/Users/vincentiuscalvin/anaconda3/envs/personal/lib/python3.8/smtplib.py", line 723, in login
    (code, resp) = self.auth(
  File "/Users/vincentiuscalvin/anaconda3/envs/personal/lib/python3.8/smtplib.py", line 646, in auth
    raise SMTPAuthenticationError(code, resp)
smtplib.SMTPAuthenticationError: (535, b'5.7.8 Username and Password not accepted. Learn more at\n5.7.8  https://support.google.com/mail/?p=BadCredentials b3sm5116311pjz.49 - gsmtp')
